{
	"name": "CVE-2024-9979",
	"description": "A flaw was found in PyO3. This vulnerability causes a use-after-free issue, potentially leading to memory corruption or crashes via unsound borrowing from weak Python references.",
	"type": "none",
	"severity": "none",
	"state": "published",
	"references": [
		"https://access.redhat.com/security/cve/CVE-2024-9979",
		"https://bugzilla.redhat.com/show_bug.cgi?id=2318646",
		"https://crates.io/crates/pyo3",
		"https://github.com/PyO3/pyo3/pull/4590",
		"https://rustsec.org/advisories/RUSTSEC-2024-0378.html"
	],
	"datetime": "2025-02-06 12:35:20",
	"connections": [],
	"devices": [],
	"distributions": [
		{
			"name": "debian",
			"version": "bookworm",
			"vendor": "debian-bookworm"
		},
		{
			"name": "debian",
			"version": "sid",
			"vendor": "debian-sid"
		},
		{
			"name": "debian",
			"version": "trixie",
			"vendor": "debian-trixie"
		}
	],
	"packages": [
		{
			"name": "rust-pyo3",
			"version": "\u003c 0.17.3-1",
			"architecture": "any",
			"manager": "apt",
			"vendor": "debian-bookworm"
		},
		{
			"name": "rust-pyo3",
			"version": "\u003c 0.22.5-1",
			"architecture": "any",
			"manager": "apt",
			"vendor": "debian-sid"
		}
	],
	"products": [],
	"programs": [],
	"weaknesses": [
		{
			"name": "CWE-416",
			"impact": "any",
			"scope": "any"
		}
	]
}